Workbook

Sheet README
A1: Phase 5: Model B* inflation forecasting workbook (origin 2023Q2)
A3: What this is | B3: The editable assumptions for the Model B* forecasting engine. You enter assumptions in everyday units (Brent in US$/bbl, annualised % changes, levels); the engine converts them into the exact variables the estimated equations use. Coefficients are fixed (estimated on 1990Q1-2023Q2) and are never re-estimated when you change an assumption.
A4: How to run | B4: Edit Inputs_A and/or Inputs_B (and Settings!forecast_end), save, then from the phase5 folder run: python p5_forecast_engine.py --workbook Phase5_Assumptions.xlsx --scenario A --with-realised python p5_forecast_engine.py --workbook Phase5_Assumptions.xlsx --scenario B --with-realised Results are written to output/ (CSV and Excel with the transformed inputs the engine used and a log of every default rule applied).
A5: Exercise A | B5: Pseudo-real-time forecast: only information available at 2023Q2. All Inputs_A cells are blank, which applies the default rules (oil flat at its 2023Q2 level, V/U flat, GSCPI AR(1), trend productivity, food with wages).
A6: Exercise B | B6: Conditional forecast: the realised paths of the drivers (pre-filled in Inputs_B from the Realised sheet) with the same fixed coefficients. Wages and all four endogenous variables are still simulated.
A7: Colour legend | B7: LIGHT BLUE fill + RED text = cell you may edit (user-specified assumption; blank = default rule) LIGHT GREEN fill = model-generated or transformed value (formulas; do not edit) GREY fill = historical realised data (History: known at the origin; Realised: outturns after it, conditional analysis only)
A8: Sheets | B8: Inputs_A / Inputs_B: your assumptions, quarterly 2023Q3-2029Q2. Model_Inputs_A / Model_Inputs_B: the transformed model inputs, so you can check that an assumption was interpreted as intended (e.g. Brent 80 becomes a log change, not the number 80). Variables: units, transformations, transition rules and default for every input. History / Realised: raw levels. Settings, Aux_Models, Coefficients: model parameters (fixed).
A9: Key transformations | B9: Brent: 400*ln(P_t/P_(t-1)), then CPI-energy growth = const + b0*that (oil bridge). CPI energy, CPI food, productivity: annualised % -> 100*ln(1+x/100) (= 400*ln of the quarterly ratio). GSCPI: 2-quarter trailing mean. V/U: level. Productivity trend: 8-quarter trailing mean. Relative prices grpe, grpf = nominal growth minus simulated wage growth (derived every quarter).
A10: Extending the horizon | B10: Set Settings!forecast_end up to 2029Q2 (three years beyond 2026Q2). Quarters without inputs use the default rules.
A11: Caveats | B11: Model B* is a reduced-form wage-price system estimated on revised data; oil, food, labour market, productivity and supply chains are exogenous here and the main source of forecast error. See METHODOLOGY_NOTE.md for the assessment and limitations.
A12: Data | B12: Current-vintage Macrobond data (Phase 3 pull pull_20261017T112636Z; oil p4_20261018T051241Z) truncated at 2023Q2 for estimation and history; outturns 2023Q3-2026Q2 from the same pull. Revised data, not real-time vintages (see METHODOLOGY_NOTE.md).
A14: Examples | B14: Editable example cell: | C14: 80 | D14: model-generated example: | E14: 4.2 | F14: historical realised example: | G14: 3.1

Sheet Settings
A1: Settings
A2: The engine reads this sheet. Light-blue/red cells may be edited.
A5: key
A6: origin | B6: 2023Q2 | C6: Forecast origin: last quarter of data used for coefficients and initial conditions (fixed).
A7: forecast_end | B7: 2026Q2 | C7: Last forecast quarter. Default 2026Q2 (end of the realised sample). Can be extended up to 2029Q2 (+3 years); the Inputs sheets already hold rows to 2029Q2.
A8: coef_file | B8: coefficients/Bstar_coefficients_2023Q2.csv | C8: Estimated Model B* coefficients (1990Q1-2023Q2), path relative to this workbook. Never re-estimated by the engine.
A9: model | B9: Model B* (four-equation SVAR-X) | C9: Authors' structure; GSCPI 2-quarter mean as the shortage term; Q2/Q3-2020 wage dummies (zero in forecasts).
A10: estimation_sample | B10: 1990Q1-2023Q2 | C10: Estimation window of every equation.
A11: data_vintage | B11: Current-vintage Macrobond data (Phase 3 pull pull_20261017T112636Z; oil p4_20261018T051241Z) truncated at 2023Q2 for estimation and history; outturns 2023Q3-2026Q2 from the same pull. Revised data, not real-time vintages (see METHODOLOGY_NOTE.md). | C11: Data used for estimation and history.

Sheet Inputs_A
A1: Exercise A: pseudo-real-time assumptions (information available at 2023Q2)
A2: Leave cells blank to use the documented default rule (see header notes and the Variables sheet). Everything blank = the pure pseudo-real-time baseline: oil flat at its 2023Q2 level, V/U flat, GSCPI mean-reverting, trend productivity, food with wages.
A5: key | C5: brent | D5: cpie_qoq | E5: cpif_qoq | F5: gscpi | G5: vu | H5: prod_qoq | I5: af_gw | J5: af_gcpi | K5: af_cf10 | L5: af_cf1
A6: Quarter | B6: Horizon status | C6: Brent crude oil | D6: CPI energy: override of the oil bridge (optional) | E6: CPI food | F6: GSCPI (supply-chain pressure) | G6: Labour-market tightness V/U | H6: Nonfarm productivity growth | I6: Add-factor: wage equation | J6: Add-factor: CPI equation | K6: Add-factor: 10y expectations eq. | L6: Add-factor: 1y expectations eq. | M6: Pre-fill source
B7: per Settings!forecast_end | C7: US$/bbl, quarterly average | D7: % change q/q, annualised | E7: % change q/q, annualised | F7: std devs, quarterly mean | G7: job openings per unemployed | H7: % change q/q, annualised | I7: pp, annualised | J7: pp, annualised | K7: pp of % per year | L7: pp of % per year
A8: 2023Q3 | B8: =IF(A8<=Settings!$B$7,"in horizon","beyond horizon (ignored)") -> in horizon | M8: blank: default rule
A9: 2023Q4 | B9: =IF(A9<=Settings!$B$7,"in horizon","beyond horizon (ignored)") -> in horizon | M9: blank: default rule
A10: 2024Q1 | B10: =IF(A10<=Settings!$B$7,"in horizon","beyond horizon (ignored)") -> in horizon | M10: blank: default rule
A11: 2024Q2 | B11: =IF(A11<=Settings!$B$7,"in horizon","beyond horizon (ignored)") -> in horizon | M11: blank: default rule
A12: 2024Q3 | B12: =IF(A12<=Settings!$B$7,"in horizon","beyond horizon (ignored)") -> in horizon | M12: blank: default rule
A13: 2024Q4 | B13: =IF(A13<=Settings!$B$7,"in horizon","beyond horizon (ignored)") -> in horizon | M13: blank: default rule
A14: 2025Q1 | B14: =IF(A14<=Settings!$B$7,"in horizon","beyond horizon (ignored)") -> in horizon | M14: blank: default rule
A15: 2025Q2 | B15: =IF(A15<=Settings!$B$7,"in horizon","beyond horizon (ignored)") -> in horizon | M15: blank: default rule
A16: 2025Q3 | B16: =IF(A16<=Settings!$B$7,"in horizon","beyond horizon (ignored)") -> in horizon | M16: blank: default rule
A17: 2025Q4 | B17: =IF(A17<=Settings!$B$7,"in horizon","beyond horizon (ignored)") -> in horizon | M17: blank: default rule
A18: 2026Q1 | B18: =IF(A18<=Settings!$B$7,"in horizon","beyond horizon (ignored)") -> in horizon | M18: blank: default rule
A19: 2026Q2 | B19: =IF(A19<=Settings!$B$7,"in horizon","beyond horizon (ignored)") -> in horizon | M19: blank: default rule
... A31: 2029Q2 | B31: =IF(A31<=Settings!$B$7,"in horizon","beyond horizon (ignored)") -> beyond horizon (ignored) | M31: blank: default rule

Sheet Inputs_B
A1: Exercise B: conditional assumptions (pre-filled with realised outturns through 2026Q2)
A2: Pre-filled from the Realised sheet (historical realised values, for conditional analysis only). Overwrite any cell to run a conditional scenario; clear a cell to fall back to the default rule. CPI-energy override takes precedence over Brent.
A5: key | C5: brent | D5: cpie_qoq | E5: cpif_qoq | F5: gscpi | G5: vu | H5: prod_qoq | I5: af_gw | J5: af_gcpi | K5: af_cf10 | L5: af_cf1
A6: Quarter | B6: Horizon status | C6: Brent crude oil | D6: CPI energy: override of the oil bridge (optional) | E6: CPI food | F6: GSCPI (supply-chain pressure) | G6: Labour-market tightness V/U | H6: Nonfarm productivity growth | I6: Add-factor: wage equation | J6: Add-factor: CPI equation | K6: Add-factor: 10y expectations eq. | L6: Add-factor: 1y expectations eq. | M6: Pre-fill source
B7: per Settings!forecast_end | C7: US$/bbl, quarterly average | D7: % change q/q, annualised | E7: % change q/q, annualised | F7: std devs, quarterly mean | G7: job openings per unemployed | H7: % change q/q, annualised | I7: pp, annualised | J7: pp, annualised | K7: pp of % per year | L7: pp of % per year
A8: 2023Q3 | B8: =IF(A8<=Settings!$B$7,"in horizon","beyond horizon (ignored)") -> in horizon | C8: 86.766667 | D8: 26.885256 | E8: 2.5225476 | F8: -0.86747033 | G8: 1.4708748 | H8: 5.0552207 | M8: Realised outturn (Realised sheet); overwrite to run a conditional scenario
A9: 2023Q4 | B9: =IF(A9<=Settings!$B$7,"in horizon","beyond horizon (ignored)") -> in horizon | C9: 84.066667 | D9: -15.25274 | E9: 2.5582554 | F9: -0.099495667 | G9: 1.3514565 | H9: 3.9403824 | M9: Realised outturn (Realised sheet); overwrite to run a conditional scenario
A10: 2024Q1 | B10: =IF(A10<=Settings!$B$7,"in horizon","beyond horizon (ignored)") -> in horizon | C10: 83.133333 | D10: 11.777767 | E10: 1.652124 | F10: -0.28298667 | G10: 1.3045564 | H10: 0.23202254 | M10: Realised outturn (Realised sheet); overwrite to run a conditional scenario
A11: 2024Q2 | B11: =IF(A11<=Settings!$B$7,"in horizon","beyond horizon (ignored)") -> in horizon | C11: 84.9 | D11: -13.654835 | E11: 2.247055 | F11: -0.61931533 | G11: 1.136691 | H11: 3.7119294 | M11: Realised outturn (Realised sheet); overwrite to run a conditional scenario
A12: 2024Q3 | B12: =IF(A12<=Settings!$B$7,"in horizon","beyond horizon (ignored)") -> in horizon | C12: 80.166667 | D12: -7.813662 | E12: 2.6385772 | F12: 0.096915333 | G12: 1.0418372 | H12: 3.6849519 | M12: Realised outturn (Realised sheet); overwrite to run a conditional scenario
A13: 2024Q4 | B13: =IF(A13<=Settings!$B$7,"in horizon","beyond horizon (ignored)") -> in horizon | C13: 74.633333 | D13: 10.905062 | E13: 3.308982 | F13: -0.36296467 | G13: 1.0610687 | H13: 1.4208753 | M13: Realised outturn (Realised sheet); overwrite to run a conditional scenario
A14: 2025Q1 | B14: =IF(A14<=Settings!$B$7,"in horizon","beyond horizon (ignored)") -> in horizon | C14: 75.666667 | D14: -1.3128637 | E14: 3.4731088 | F14: -0.208122 | G14: 1.0248329 | H14: -0.88331423 | M14: Realised outturn (Realised sheet); overwrite to run a conditional scenario
A15: 2025Q2 | B15: =IF(A15<=Settings!$B$7,"in horizon","beyond horizon (ignored)") -> in horizon | C15: 67.8 | D15: -3.3251572 | E15: 2.558191 | F15: -0.053499 | G15: 1.0072237 | H15: 4.1886149 | M15: Realised outturn (Realised sheet); overwrite to run a conditional scenario
A16: 2025Q3 | B16: =IF(A16<=Settings!$B$7,"in horizon","beyond horizon (ignored)") -> in horizon | C16: 69.066667 | D16: 6.1267213 | E16: 3.1206963 | F16: -0.029837667 | G16: 0.95147594 | H16: 5.2066565 | M16: Realised outturn (Realised sheet); overwrite to run a conditional scenario
A17: 2025Q4 | B17: =IF(A17<=Settings!$B$7,"in horizon","beyond horizon (ignored)") -> in horizon | C17: 63.666667 | D17: 7.2035426 | E17: 3.0104295 | F17: 0.033617 | G17: 0.89506898 | H17: 1.5771579 | M17: Realised outturn (Realised sheet); overwrite to run a conditional scenario
A18: 2026Q1 | B18: =IF(A18<=Settings!$B$7,"in horizon","beyond horizon (ignored)") -> in horizon | C18: 80.533333 | D18: 46.098218 | E18: 2.3073577 | F18: 0.49244233 | G18: 0.9490937 | H18: 0.82027406 | M18: Realised outturn (Realised sheet); overwrite to run a conditional scenario
A19: 2026Q2 | B19: =IF(A19<=Settings!$B$7,"in horizon","beyond horizon (ignored)") -> in horizon | C19: 104.43333 | D19: 6.8851971 | E19: 3.5144901 | F19: 1.5994187 | G19: 1.024341 | H19: 1.4223105 | M19: Realised outturn (Realised sheet); overwrite to run a conditional scenario
A20: 2026Q3 | B20: =IF(A20<=Settings!$B$7,"in horizon","beyond horizon (ignored)") -> beyond horizon (ignored) | M20: blank: default rule
A21: 2026Q4 | B21: =IF(A21<=Settings!$B$7,"in horizon","beyond horizon (ignored)") -> beyond horizon (ignored) | M21: blank: default rule
A22: 2027Q1 | B22: =IF(A22<=Settings!$B$7,"in horizon","beyond horizon (ignored)") -> beyond horizon (ignored) | M22: blank: default rule
A23: 2027Q2 | B23: =IF(A23<=Settings!$B$7,"in horizon","beyond horizon (ignored)") -> beyond horizon (ignored) | M23: blank: default rule
A24: 2027Q3 | B24: =IF(A24<=Settings!$B$7,"in horizon","beyond horizon (ignored)") -> beyond horizon (ignored) | M24: blank: default rule
A25: 2027Q4 | B25: =IF(A25<=Settings!$B$7,"in horizon","beyond horizon (ignored)") -> beyond horizon (ignored) | M25: blank: default rule
A26: 2028Q1 | B26: =IF(A26<=Settings!$B$7,"in horizon","beyond horizon (ignored)") -> beyond horizon (ignored) | M26: blank: default rule
A27: 2028Q2 | B27: =IF(A27<=Settings!$B$7,"in horizon","beyond horizon (ignored)") -> beyond horizon (ignored) | M27: blank: default rule
A28: 2028Q3 | B28: =IF(A28<=Settings!$B$7,"in horizon","beyond horizon (ignored)") -> beyond horizon (ignored) | M28: blank: default rule
A29: 2028Q4 | B29: =IF(A29<=Settings!$B$7,"in horizon","beyond horizon (ignored)") -> beyond horizon (ignored) | M29: blank: default rule
A30: 2029Q1 | B30: =IF(A30<=Settings!$B$7,"in horizon","beyond horizon (ignored)") -> beyond horizon (ignored) | M30: blank: default rule
A31: 2029Q2 | B31: =IF(A31<=Settings!$B$7,"in horizon","beyond horizon (ignored)") -> beyond horizon (ignored) | M31: blank: default rule

Sheet Model_Inputs_A
A1: Model inputs actually used (Exercise A): transformed assumptions
A2: Light green = formulas. This is how the engine interprets Inputs_A (the engine recomputes the same transformations in Python; a test confirms they agree). Relative prices grpe = gE - gw and grpf = gF - gw need the simulated wage growth, so they are produced by the engine (see the engine's Model_Inputs_Engine sheet).
A6: Quarter | B6: Status | C6: Brent used | D6: Brent growth | E6: CPI energy growth from oil bridge | F6: CPI energy growth USED (model gE) | G6: CPI food growth USED (model gF) | H6: GSCPI used | I6: Shortage term (2-qtr mean) | J6: V/U used | K6: Productivity growth used | L6: Trend productivity magpty (8-qtr mean) | M6: Add-factor gw | N6: Add-factor gcpi | O6: Add-factor cf10 | P6: Add-factor cf1 | Q6: Brent: source | R6: CPI energy: source | S6: CPI food: source | T6: GSCPI: source | U6: V/U: source | V6: Productivity: source
C7: US$/bbl | D7: 400*dln | E7: 400*dln | F7: 400*dln | G7: 400*dln | H7: std devs | I7: std devs | J7: ratio | K7: 400*dln | L7: 400*dln | M7: pp | N7: pp | O7: pp | P7: pp
A8: 2021Q1 | B8: History | C8: =History!B16 -> 60.6 | F8: =History!N16 -> 44.055904 | G8: =History!O16 -> 1.2610235 | H8: =History!H16 -> 1.9166773 | I8: =History!T16 -> 1.3591037 | J8: =History!I16 -> 0.78176069 | K8: =History!R16 -> 2.8649674 | L8: =History!S16 -> 4.2386431
A9: 2021Q2 | B9: History | C9: =History!B17 -> 68.633333 | D9: =400*LN(C9/C8) -> 49.793373 | F9: =History!N17 -> 6.8841559 | G9: =History!O17 -> 6.3708245 | H9: =History!H17 -> 2.8931447 | I9: =History!T17 -> 2.404911 | J9: =History!I17 -> 1.0394455 | K9: =History!R17 -> 0.83221266 | L9: =History!S17 -> 4.0353301
A10: 2021Q3 | B10: History | C10: =History!B18 -> 73 | D10: =400*LN(C10/C9) -> 24.672446 | F10: =History!N18 -> 19.546804 | G10: =History!O18 -> 7.7065267 | H10: =History!H18 -> 3.248395 | I10: =History!T18 -> 3.0707698 | J10: =History!I18 -> 1.3282812 | K10: =History!R18 -> -2.4369499 | L10: =History!S18 -> 3.1715554
A11: 2021Q4 | B11: History | C11: =History!B19 -> 79.6 | D11: =400*LN(C11/C10) -> 34.621861 | F11: =History!N19 -> 35.247976 | G11: =History!O19 -> 9.0604705 | H11: =History!H19 -> 4.2794147 | I11: =History!T19 -> 3.7639048 | J11: =History!I19 -> 1.6638248 | K11: =History!R19 -> 2.2649099 | L11: =History!S19 -> 2.9891538
A12: 2022Q1 | B12: History | C12: =History!B20 -> 98.966667 | D12: =400*LN(C12/C11) -> 87.1076 | F12: =History!N20 -> 49.379776 | G12: =History!O20 -> 10.606802 | H12: =History!H20 -> 3.1419513 | I12: =History!T20 -> 3.710683 | J12: =History!I20 -> 1.8639949 | K12: =History!R20 -> -5.0579243 | L12: =History!S20 -> 2.5590281
A13: 2022Q2 | B13: History | C13: =History!B21 -> 112.76667 | D13: =400*LN(C13/C12) -> 52.215078 | F13: =History!N21 -> 34.565614 | G13: =History!O21 -> 12.377149 | H13: =History!H21 -> 2.935063 | I13: =History!T21 -> 3.0385072 | J13: =History!I21 -> 1.9320854 | K13: =History!R21 -> -2.9735579 | L13: =History!S21 -> -0.18801475
A14: 2022Q3 | B14: History | C14: =History!B22 -> 99.233333 | D14: =400*LN(C14/C13) -> -51.138723 | F14: =History!N22 -> -46.617389 | G14: =History!O22 -> 10.447792 | H14: =History!H22 -> 1.5306163 | I14: =History!T22 -> 2.2328397 | J14: =History!I22 -> 1.8631929 | K14: =History!R22 -> 0.23036525 | L14: =History!S22 -> -0.93613823
A15: 2022Q4 | B15: History | C15: =History!B23 -> 88.366667 | D15: =400*LN(C15/C14) -> -46.391662 | F15: =History!N23 -> -10.714022 | G15: =History!O23 -> 6.2305252 | H15: =History!H23 -> 1.3098957 | I15: =History!T23 -> 1.420256 | J15: =History!I23 -> 1.81216 | K15: =History!R23 -> 2.2745767 | L15: =History!S23 -> -0.25017501
A16: 2023Q1 | B16: History | C16: =History!B24 -> 81.433333 | D16: =400*LN(C16/C15) -> -32.684054 | F16: =History!N24 -> -4.8658536 | G16: =History!O24 -> 3.4350358 | H16: =History!H24 -> -0.15327933 | I16: =History!T24 -> 0.57830817 | J16: =History!I24 -> 1.693347 | K16: =History!R24 -> 0.91129859 | L16: =History!S24 -> -0.49438362
A17: 2023Q2 | B17: History | C17: =History!B25 -> 78.233333 | D17: =400*LN(C17/C16) -> -16.03555 | F17: =History!N25 -> -10.249406 | G17: =History!O25 -> 2.253478 | H17: =History!H25 -> -1.3193497 | I17: =History!T25 -> -0.7363145 | J17: =History!I25 -> 1.6004715 | K17: =History!R25 -> 3.9909759 | L17: =History!S25 -> -0.099538212
A18: 2023Q3 | B18: =IF(A18<=Settings!$B$7,"Forecast","Beyond horizon") -> Forecast | C18: =IF(ISBLANK(Inputs_A!C8),C17,Inputs_A!C8) -> 78.233333 | D18: =400*LN(C18/C17) -> 0 | E18: =Aux_Models!$B$6+Aux_Models!$B$7*D18 -> 1.8686902 | F18: =IF(ISBLANK(Inputs_A!D8),E18,100*LN(1+Inputs_A!D8/100)) -> 1.8686902 | G18: =IF(ISBLANK(Inputs_A!E8),"wage-linked",100*LN(1+Inputs_A!E8/100)) -> wage-linked | H18: =IF(ISBLANK(Inputs_A!F8),Aux_Models!$B$8+Aux_Models!$B$9*H17,Inputs_A!F8) -> -1.1438549 | I18: =AVERAGE(H17:H18) -> -1.2316023 | J18: =IF(ISBLANK(Inputs_A!G8),J17,Inputs_A!G8) -> 1.6004715 | K18: =IF(ISBLANK(Inputs_A!H8),K10,100*LN(1+Inputs_A!H8/100)) -> -2.4369499 | L18: =AVERAGE(K11:K18) -> -0.099538212 | M18: =IF(ISBLANK(Inputs_A!I8),0,Inputs_A!I8) -> 0 | N18: =IF(ISBLANK(Inputs_A!J8),0,Inputs_A!J8) -> 0 | O18: =IF(ISBLANK(Inputs_A!K8),0,Inputs_A!K8) -> 0 | P18: =IF(ISBLANK(Inputs_A!L8),0,Inputs_A!L8) -> 0 | Q18: =IF(ISBLANK(Inputs_A!C8),"default: carried forward","user") -> default: carried forward | R18: =IF(NOT(ISBLANK(Inputs_A!D8)),"user (CPI energy override)",IF(ISBLANK(Inputs_A!C8),"oil bridge, Brent default","oil bridge, Brent user")) -> oil bridge, Brent default | S18: =IF(ISBLANK(Inputs_A!E8),"default: wage-linked","user") -> default: wage-linked | T18: =IF(ISBLANK(Inputs_A!F8),"default: AR(1)","user") -> default: AR(1) | U18: =IF(ISBLANK(Inputs_A!G8),"default: carried forward","user") -> default: carried forward | V18: =IF(ISBLANK(Inputs_A!H8),"default: trend held","user") -> default: trend held
A19: 2023Q4 | B19: =IF(A19<=Settings!$B$7,"Forecast","Beyond horizon") -> Forecast | C19: =IF(ISBLANK(Inputs_A!C9),C18,Inputs_A!C9) -> 78.233333 | D19: =400*LN(C19/C18) -> 0 | E19: =Aux_Models!$B$6+Aux_Models!$B$7*D19 -> 1.8686902 | F19: =IF(ISBLANK(Inputs_A!D9),E19,100*LN(1+Inputs_A!D9/100)) -> 1.8686902 | G19: =IF(ISBLANK(Inputs_A!E9),"wage-linked",100*LN(1+Inputs_A!E9/100)) -> wage-linked | H19: =IF(ISBLANK(Inputs_A!F9),Aux_Models!$B$8+Aux_Models!$B$9*H18,Inputs_A!F9) -> -0.99271864 | I19: =AVERAGE(H18:H19) -> -1.0682868 | J19: =IF(ISBLANK(Inputs_A!G9),J18,Inputs_A!G9) -> 1.6004715 | K19: =IF(ISBLANK(Inputs_A!H9),K11,100*LN(1+Inputs_A!H9/100)) -> 2.2649099 | L19: =AVERAGE(K12:K19) -> -0.099538212 | M19: =IF(ISBLANK(Inputs_A!I9),0,Inputs_A!I9) -> 0 | N19: =IF(ISBLANK(Inputs_A!J9),0,Inputs_A!J9) -> 0 | O19: =IF(ISBLANK(Inputs_A!K9),0,Inputs_A!K9) -> 0 | P19: =IF(ISBLANK(Inputs_A!L9),0,Inputs_A!L9) -> 0 | Q19: =IF(ISBLANK(Inputs_A!C9),"default: carried forward","user") -> default: carried forward | R19: =IF(NOT(ISBLANK(Inputs_A!D9)),"user (CPI energy override)",IF(ISBLANK(Inputs_A!C9),"oil bridge, Brent default","oil bridge, Brent user")) -> oil bridge, Brent default | S19: =IF(ISBLANK(Inputs_A!E9),"default: wage-linked","user") -> default: wage-linked | T19: =IF(ISBLANK(Inputs_A!F9),"default: AR(1)","user") -> default: AR(1) | U19: =IF(ISBLANK(Inputs_A!G9),"default: carried forward","user") -> default: carried forward | V19: =IF(ISBLANK(Inputs_A!H9),"default: trend held","user") -> default: trend held
A20: 2024Q1 | B20: =IF(A20<=Settings!$B$7,"Forecast","Beyond horizon") -> Forecast | C20: =IF(ISBLANK(Inputs_A!C10),C19,Inputs_A!C10) -> 78.233333 | D20: =400*LN(C20/C19) -> 0 | E20: =Aux_Models!$B$6+Aux_Models!$B$7*D20 -> 1.8686902 | F20: =IF(ISBLANK(Inputs_A!D10),E20,100*LN(1+Inputs_A!D10/100)) -> 1.8686902 | G20: =IF(ISBLANK(Inputs_A!E10),"wage-linked",100*LN(1+Inputs_A!E10/100)) -> wage-linked | H20: =IF(ISBLANK(Inputs_A!F10),Aux_Models!$B$8+Aux_Models!$B$9*H19,Inputs_A!F10) -> -0.86255995 | I20: =AVERAGE(H19:H20) -> -0.9276393 | J20: =IF(ISBLANK(Inputs_A!G10),J19,Inputs_A!G10) -> 1.6004715 | K20: =IF(ISBLANK(Inputs_A!H10),K12,100*LN(1+Inputs_A!H10/100)) -> -5.0579243 | L20: =AVERAGE(K13:K20) -> -0.099538212 | M20: =IF(ISBLANK(Inputs_A!I10),0,Inputs_A!I10) -> 0 | N20: =IF(ISBLANK(Inputs_A!J10),0,Inputs_A!J10) -> 0 | O20: =IF(ISBLANK(Inputs_A!K10),0,Inputs_A!K10) -> 0 | P20: =IF(ISBLANK(Inputs_A!L10),0,Inputs_A!L10) -> 0 | Q20: =IF(ISBLANK(Inputs_A!C10),"default: carried forward","user") -> default: carried forward | R20: =IF(NOT(ISBLANK(Inputs_A!D10)),"user (CPI energy override)",IF(ISBLANK(Inputs_A!C10),"oil bridge, Brent default","oil bridge, Brent user")) -> oil bridge, Brent default | S20: =IF(ISBLANK(Inputs_A!E10),"default: wage-linked","user") -> default: wage-linked | T20: =IF(ISBLANK(Inputs_A!F10),"default: AR(1)","user") -> default: AR(1) | U20: =IF(ISBLANK(Inputs_A!G10),"default: carried forward","user") -> default: carried forward | V20: =IF(ISBLANK(Inputs_A!H10),"default: trend held","user") -> default: trend held
A21: 2024Q2 | B21: =IF(A21<=Settings!$B$7,"Forecast","Beyond horizon") -> Forecast | C21: =IF(ISBLANK(Inputs_A!C11),C20,Inputs_A!C11) -> 78.233333 | D21: =400*LN(C21/C20) -> 0 | E21: =Aux_Models!$B$6+Aux_Models!$B$7*D21 -> 1.8686902 | F21: =IF(ISBLANK(Inputs_A!D11),E21,100*LN(1+Inputs_A!D11/100)) -> 1.8686902 | G21: =IF(ISBLANK(Inputs_A!E11),"wage-linked",100*LN(1+Inputs_A!E11/100)) -> wage-linked | H21: =IF(ISBLANK(Inputs_A!F11),Aux_Models!$B$8+Aux_Models!$B$9*H20,Inputs_A!F11) -> -0.75046717 | I21: =AVERAGE(H20:H21) -> -0.80651356 | J21: =IF(ISBLANK(Inputs_A!G11),J20,Inputs_A!G11) -> 1.6004715 | K21: =IF(ISBLANK(Inputs_A!H11),K13,100*LN(1+Inputs_A!H11/100)) -> -2.9735579 | L21: =AVERAGE(K14:K21) -> -0.099538212 | M21: =IF(ISBLANK(Inputs_A!I11),0,Inputs_A!I11) -> 0 | N21: =IF(ISBLANK(Inputs_A!J11),0,Inputs_A!J11) -> 0 | O21: =IF(ISBLANK(Inputs_A!K11),0,Inputs_A!K11) -> 0 | P21: =IF(ISBLANK(Inputs_A!L11),0,Inputs_A!L11) -> 0 | Q21: =IF(ISBLANK(Inputs_A!C11),"default: carried forward","user") -> default: carried forward | R21: =IF(NOT(ISBLANK(Inputs_A!D11)),"user (CPI energy override)",IF(ISBLANK(Inputs_A!C11),"oil bridge, Brent default","oil bridge, Brent user")) -> oil bridge, Brent default | S21: =IF(ISBLANK(Inputs_A!E11),"default: wage-linked","user") -> default: wage-linked | T21: =IF(ISBLANK(Inputs_A!F11),"default: AR(1)","user") -> default: AR(1) | U21: =IF(ISBLANK(Inputs_A!G11),"default: carried forward","user") -> default: carried forward | V21: =IF(ISBLANK(Inputs_A!H11),"default: trend held","user") -> default: trend held
A22: 2024Q3 | B22: =IF(A22<=Settings!$B$7,"Forecast","Beyond horizon") -> Forecast | C22: =IF(ISBLANK(Inputs_A!C12),C21,Inputs_A!C12) -> 78.233333 | D22: =400*LN(C22/C21) -> 0 | E22: =Aux_Models!$B$6+Aux_Models!$B$7*D22 -> 1.8686902 | F22: =IF(ISBLANK(Inputs_A!D12),E22,100*LN(1+Inputs_A!D12/100)) -> 1.8686902 | G22: =IF(ISBLANK(Inputs_A!E12),"wage-linked",100*LN(1+Inputs_A!E12/100)) -> wage-linked | H22: =IF(ISBLANK(Inputs_A!F12),Aux_Models!$B$8+Aux_Models!$B$9*H21,Inputs_A!F12) -> -0.65393276 | I22: =AVERAGE(H21:H22) -> -0.70219996 | J22: =IF(ISBLANK(Inputs_A!G12),J21,Inputs_A!G12) -> 1.6004715 | K22: =IF(ISBLANK(Inputs_A!H12),K14,100*LN(1+Inputs_A!H12/100)) -> 0.23036525 | L22: =AVERAGE(K15:K22) -> -0.099538212 | M22: =IF(ISBLANK(Inputs_A!I12),0,Inputs_A!I12) -> 0 | N22: =IF(ISBLANK(Inputs_A!J12),0,Inputs_A!J12) -> 0 | O22: =IF(ISBLANK(Inputs_A!K12),0,Inputs_A!K12) -> 0 | P22: =IF(ISBLANK(Inputs_A!L12),0,Inputs_A!L12) -> 0 | Q22: =IF(ISBLANK(Inputs_A!C12),"default: carried forward","user") -> default: carried forward | R22: =IF(NOT(ISBLANK(Inputs_A!D12)),"user (CPI energy override)",IF(ISBLANK(Inputs_A!C12),"oil bridge, Brent default","oil bridge, Brent user")) -> oil bridge, Brent default | S22: =IF(ISBLANK(Inputs_A!E12),"default: wage-linked","user") -> default: wage-linked | T22: =IF(ISBLANK(Inputs_A!F12),"default: AR(1)","user") -> default: AR(1) | U22: =IF(ISBLANK(Inputs_A!G12),"default: carried forward","user") -> default: carried forward | V22: =IF(ISBLANK(Inputs_A!H12),"default: trend held","user") -> default: trend held
A23: 2024Q4 | B23: =IF(A23<=Settings!$B$7,"Forecast","Beyond horizon") -> Forecast | C23: =IF(ISBLANK(Inputs_A!C13),C22,Inputs_A!C13) -> 78.233333 | D23: =400*LN(C23/C22) -> 0 | E23: =Aux_Models!$B$6+Aux_Models!$B$7*D23 -> 1.8686902 | F23: =IF(ISBLANK(Inputs_A!D13),E23,100*LN(1+Inputs_A!D13/100)) -> 1.8686902 | G23: =IF(ISBLANK(Inputs_A!E13),"wage-linked",100*LN(1+Inputs_A!E13/100)) -> wage-linked | H23: =IF(ISBLANK(Inputs_A!F13),Aux_Models!$B$8+Aux_Models!$B$9*H22,Inputs_A!F13) -> -0.57079723 | I23: =AVERAGE(H22:H23) -> -0.61236499 | J23: =IF(ISBLANK(Inputs_A!G13),J22,Inputs_A!G13) -> 1.6004715 | K23: =IF(ISBLANK(Inputs_A!H13),K15,100*LN(1+Inputs_A!H13/100)) -> 2.2745767 | L23: =AVERAGE(K16:K23) -> -0.099538212 | M23: =IF(ISBLANK(Inputs_A!I13),0,Inputs_A!I13) -> 0 | N23: =IF(ISBLANK(Inputs_A!J13),0,Inputs_A!J13) -> 0 | O23: =IF(ISBLANK(Inputs_A!K13),0,Inputs_A!K13) -> 0 | P23: =IF(ISBLANK(Inputs_A!L13),0,Inputs_A!L13) -> 0 | Q23: =IF(ISBLANK(Inputs_A!C13),"default: carried forward","user") -> default: carried forward | R23: =IF(NOT(ISBLANK(Inputs_A!D13)),"user (CPI energy override)",IF(ISBLANK(Inputs_A!C13),"oil bridge, Brent default","oil bridge, Brent user")) -> oil bridge, Brent default | S23: =IF(ISBLANK(Inputs_A!E13),"default: wage-linked","user") -> default: wage-linked | T23: =IF(ISBLANK(Inputs_A!F13),"default: AR(1)","user") -> default: AR(1) | U23: =IF(ISBLANK(Inputs_A!G13),"default: carried forward","user") -> default: carried forward | V23: =IF(ISBLANK(Inputs_A!H13),"default: trend held","user") -> default: trend held
A24: 2025Q1 | B24: =IF(A24<=Settings!$B$7,"Forecast","Beyond horizon") -> Forecast | C24: =IF(ISBLANK(Inputs_A!C14),C23,Inputs_A!C14) -> 78.233333 | D24: =400*LN(C24/C23) -> 0 | E24: =Aux_Models!$B$6+Aux_Models!$B$7*D24 -> 1.8686902 | F24: =IF(ISBLANK(Inputs_A!D14),E24,100*LN(1+Inputs_A!D14/100)) -> 1.8686902 | G24: =IF(ISBLANK(Inputs_A!E14),"wage-linked",100*LN(1+Inputs_A!E14/100)) -> wage-linked | H24: =IF(ISBLANK(Inputs_A!F14),Aux_Models!$B$8+Aux_Models!$B$9*H23,Inputs_A!F14) -> -0.49920084 | I24: =AVERAGE(H23:H24) -> -0.53499903 | J24: =IF(ISBLANK(Inputs_A!G14),J23,Inputs_A!G14) -> 1.6004715 | K24: =IF(ISBLANK(Inputs_A!H14),K16,100*LN(1+Inputs_A!H14/100)) -> 0.91129859 | L24: =AVERAGE(K17:K24) -> -0.099538212 | M24: =IF(ISBLANK(Inputs_A!I14),0,Inputs_A!I14) -> 0 | N24: =IF(ISBLANK(Inputs_A!J14),0,Inputs_A!J14) -> 0 | O24: =IF(ISBLANK(Inputs_A!K14),0,Inputs_A!K14) -> 0 | P24: =IF(ISBLANK(Inputs_A!L14),0,Inputs_A!L14) -> 0 | Q24: =IF(ISBLANK(Inputs_A!C14),"default: carried forward","user") -> default: carried forward | R24: =IF(NOT(ISBLANK(Inputs_A!D14)),"user (CPI energy override)",IF(ISBLANK(Inputs_A!C14),"oil bridge, Brent default","oil bridge, Brent user")) -> oil bridge, Brent default | S24: =IF(ISBLANK(Inputs_A!E14),"default: wage-linked","user") -> default: wage-linked | T24: =IF(ISBLANK(Inputs_A!F14),"default: AR(1)","user") -> default: AR(1) | U24: =IF(ISBLANK(Inputs_A!G14),"default: carried forward","user") -> default: carried forward | V24: =IF(ISBLANK(Inputs_A!H14),"default: trend held","user") -> default: trend held
A25: 2025Q2 | B25: =IF(A25<=Settings!$B$7,"Forecast","Beyond horizon") -> Forecast | C25: =IF(ISBLANK(Inputs_A!C15),C24,Inputs_A!C15) -> 78.233333 | D25: =400*LN(C25/C24) -> 0 | E25: =Aux_Models!$B$6+Aux_Models!$B$7*D25 -> 1.8686902 | F25: =IF(ISBLANK(Inputs_A!D15),E25,100*LN(1+Inputs_A!D15/100)) -> 1.8686902 | G25: =IF(ISBLANK(Inputs_A!E15),"wage-linked",100*LN(1+Inputs_A!E15/100)) -> wage-linked | H25: =IF(ISBLANK(Inputs_A!F15),Aux_Models!$B$8+Aux_Models!$B$9*H24,Inputs_A!F15) -> -0.43754196 | I25: =AVERAGE(H24:H25) -> -0.4683714 | J25: =IF(ISBLANK(Inputs_A!G15),J24,Inputs_A!G15) -> 1.6004715 | K25: =IF(ISBLANK(Inputs_A!H15),K17,100*LN(1+Inputs_A!H15/100)) -> 3.9909759 | L25: =AVERAGE(K18:K25) -> -0.099538212 | M25: =IF(ISBLANK(Inputs_A!I15),0,Inputs_A!I15) -> 0 | N25: =IF(ISBLANK(Inputs_A!J15),0,Inputs_A!J15) -> 0 | O25: =IF(ISBLANK(Inputs_A!K15),0,Inputs_A!K15) -> 0 | P25: =IF(ISBLANK(Inputs_A!L15),0,Inputs_A!L15) -> 0 | Q25: =IF(ISBLANK(Inputs_A!C15),"default: carried forward","user") -> default: carried forward | R25: =IF(NOT(ISBLANK(Inputs_A!D15)),"user (CPI energy override)",IF(ISBLANK(Inputs_A!C15),"oil bridge, Brent default","oil bridge, Brent user")) -> oil bridge, Brent default | S25: =IF(ISBLANK(Inputs_A!E15),"default: wage-linked","user") -> default: wage-linked | T25: =IF(ISBLANK(Inputs_A!F15),"default: AR(1)","user") -> default: AR(1) | U25: =IF(ISBLANK(Inputs_A!G15),"default: carried forward","user") -> default: carried forward | V25: =IF(ISBLANK(Inputs_A!H15),"default: trend held","user") -> default: trend held
A26: 2025Q3 | B26: =IF(A26<=Settings!$B$7,"Forecast","Beyond horizon") -> Forecast | C26: =IF(ISBLANK(Inputs_A!C16),C25,Inputs_A!C16) -> 78.233333 | D26: =400*LN(C26/C25) -> 0 | E26: =Aux_Models!$B$6+Aux_Models!$B$7*D26 -> 1.8686902 | F26: =IF(ISBLANK(Inputs_A!D16),E26,100*LN(1+Inputs_A!D16/100)) -> 1.8686902 | G26: =IF(ISBLANK(Inputs_A!E16),"wage-linked",100*LN(1+Inputs_A!E16/100)) -> wage-linked | H26: =IF(ISBLANK(Inputs_A!F16),Aux_Models!$B$8+Aux_Models!$B$9*H25,Inputs_A!F16) -> -0.38444127 | I26: =AVERAGE(H25:H26) -> -0.41099161 | J26: =IF(ISBLANK(Inputs_A!G16),J25,Inputs_A!G16) -> 1.6004715 | K26: =IF(ISBLANK(Inputs_A!H16),K18,100*LN(1+Inputs_A!H16/100)) -> -2.4369499 | L26: =AVERAGE(K19:K26) -> -0.099538212 | M26: =IF(ISBLANK(Inputs_A!I16),0,Inputs_A!I16) -> 0 | N26: =IF(ISBLANK(Inputs_A!J16),0,Inputs_A!J16) -> 0 | O26: =IF(ISBLANK(Inputs_A!K16),0,Inputs_A!K16) -> 0 | P26: =IF(ISBLANK(Inputs_A!L16),0,Inputs_A!L16) -> 0 | Q26: =IF(ISBLANK(Inputs_A!C16),"default: carried forward","user") -> default: carried forward | R26: =IF(NOT(ISBLANK(Inputs_A!D16)),"user (CPI energy override)",IF(ISBLANK(Inputs_A!C16),"oil bridge, Brent default","oil bridge, Brent user")) -> oil bridge, Brent default | S26: =IF(ISBLANK(Inputs_A!E16),"default: wage-linked","user") -> default: wage-linked | T26: =IF(ISBLANK(Inputs_A!F16),"default: AR(1)","user") -> default: AR(1) | U26: =IF(ISBLANK(Inputs_A!G16),"default: carried forward","user") -> default: carried forward | V26: =IF(ISBLANK(Inputs_A!H16),"default: trend held","user") -> default: trend held
A27: 2025Q4 | B27: =IF(A27<=Settings!$B$7,"Forecast","Beyond horizon") -> Forecast | C27: =IF(ISBLANK(Inputs_A!C17),C26,Inputs_A!C17) -> 78.233333 | D27: =400*LN(C27/C26) -> 0 | E27: =Aux_Models!$B$6+Aux_Models!$B$7*D27 -> 1.8686902 | F27: =IF(ISBLANK(Inputs_A!D17),E27,100*LN(1+Inputs_A!D17/100)) -> 1.8686902 | G27: =IF(ISBLANK(Inputs_A!E17),"wage-linked",100*LN(1+Inputs_A!E17/100)) -> wage-linked | H27: =IF(ISBLANK(Inputs_A!F17),Aux_Models!$B$8+Aux_Models!$B$9*H26,Inputs_A!F17) -> -0.33871091 | I27: =AVERAGE(H26:H27) -> -0.36157609 | J27: =IF(ISBLANK(Inputs_A!G17),J26,Inputs_A!G17) -> 1.6004715 | K27: =IF(ISBLANK(Inputs_A!H17),K19,100*LN(1+Inputs_A!H17/100)) -> 2.2649099 | L27: =AVERAGE(K20:K27) -> -0.099538212 | M27: =IF(ISBLANK(Inputs_A!I17),0,Inputs_A!I17) -> 0 | N27: =IF(ISBLANK(Inputs_A!J17),0,Inputs_A!J17) -> 0 | O27: =IF(ISBLANK(Inputs_A!K17),0,Inputs_A!K17) -> 0 | P27: =IF(ISBLANK(Inputs_A!L17),0,Inputs_A!L17) -> 0 | Q27: =IF(ISBLANK(Inputs_A!C17),"default: carried forward","user") -> default: carried forward | R27: =IF(NOT(ISBLANK(Inputs_A!D17)),"user (CPI energy override)",IF(ISBLANK(Inputs_A!C17),"oil bridge, Brent default","oil bridge, Brent user")) -> oil bridge, Brent default | S27: =IF(ISBLANK(Inputs_A!E17),"default: wage-linked","user") -> default: wage-linked | T27: =IF(ISBLANK(Inputs_A!F17),"default: AR(1)","user") -> default: AR(1) | U27: =IF(ISBLANK(Inputs_A!G17),"default: carried forward","user") -> default: carried forward | V27: =IF(ISBLANK(Inputs_A!H17),"default: trend held","user") -> default: trend held
A28: 2026Q1 | B28: =IF(A28<=Settings!$B$7,"Forecast","Beyond horizon") -> Forecast | C28: =IF(ISBLANK(Inputs_A!C18),C27,Inputs_A!C18) -> 78.233333 | D28: =400*LN(C28/C27) -> 0 | E28: =Aux_Models!$B$6+Aux_Models!$B$7*D28 -> 1.8686902 | F28: =IF(ISBLANK(Inputs_A!D18),E28,100*LN(1+Inputs_A!D18/100)) -> 1.8686902 | G28: =IF(ISBLANK(Inputs_A!E18),"wage-linked",100*LN(1+Inputs_A!E18/100)) -> wage-linked | H28: =IF(ISBLANK(Inputs_A!F18),Aux_Models!$B$8+Aux_Models!$B$9*H27,Inputs_A!F18) -> -0.29932788 | I28: =AVERAGE(H27:H28) -> -0.3190194 | J28: =IF(ISBLANK(Inputs_A!G18),J27,Inputs_A!G18) -> 1.6004715 | K28: =IF(ISBLANK(Inputs_A!H18),K20,100*LN(1+Inputs_A!H18/100)) -> -5.0579243 | L28: =AVERAGE(K21:K28) -> -0.099538212 | M28: =IF(ISBLANK(Inputs_A!I18),0,Inputs_A!I18) -> 0 | N28: =IF(ISBLANK(Inputs_A!J18),0,Inputs_A!J18) -> 0 | O28: =IF(ISBLANK(Inputs_A!K18),0,Inputs_A!K18) -> 0 | P28: =IF(ISBLANK(Inputs_A!L18),0,Inputs_A!L18) -> 0 | Q28: =IF(ISBLANK(Inputs_A!C18),"default: carried forward","user") -> default: carried forward | R28: =IF(NOT(ISBLANK(Inputs_A!D18)),"user (CPI energy override)",IF(ISBLANK(Inputs_A!C18),"oil bridge, Brent default","oil bridge, Brent user")) -> oil bridge, Brent default | S28: =IF(ISBLANK(Inputs_A!E18),"default: wage-linked","user") -> default: wage-linked | T28: =IF(ISBLANK(Inputs_A!F18),"default: AR(1)","user") -> default: AR(1) | U28: =IF(ISBLANK(Inputs_A!G18),"default: carried forward","user") -> default: carried forward | V28: =IF(ISBLANK(Inputs_A!H18),"default: trend held","user") -> default: trend held
A29: 2026Q2 | B29: =IF(A29<=Settings!$B$7,"Forecast","Beyond horizon") -> Forecast | C29: =IF(ISBLANK(Inputs_A!C19),C28,Inputs_A!C19) -> 78.233333 | D29: =400*LN(C29/C28) -> 0 | E29: =Aux_Models!$B$6+Aux_Models!$B$7*D29 -> 1.8686902 | F29: =IF(ISBLANK(Inputs_A!D19),E29,100*LN(1+Inputs_A!D19/100)) -> 1.8686902 | G29: =IF(ISBLANK(Inputs_A!E19),"wage-linked",100*LN(1+Inputs_A!E19/100)) -> wage-linked | H29: =IF(ISBLANK(Inputs_A!F19),Aux_Models!$B$8+Aux_Models!$B$9*H28,Inputs_A!F19) -> -0.26541118 | I29: =AVERAGE(H28:H29) -> -0.28236953 | J29: =IF(ISBLANK(Inputs_A!G19),J28,Inputs_A!G19) -> 1.6004715 | K29: =IF(ISBLANK(Inputs_A!H19),K21,100*LN(1+Inputs_A!H19/100)) -> -2.9735579 | L29: =AVERAGE(K22:K29) -> -0.099538212 | M29: =IF(ISBLANK(Inputs_A!I19),0,Inputs_A!I19) -> 0 | N29: =IF(ISBLANK(Inputs_A!J19),0,Inputs_A!J19) -> 0 | O29: =IF(ISBLANK(Inputs_A!K19),0,Inputs_A!K19) -> 0 | P29: =IF(ISBLANK(Inputs_A!L19),0,Inputs_A!L19) -> 0 | Q29: =IF(ISBLANK(Inputs_A!C19),"default: carried forward","user") -> default: carried forward | R29: =IF(NOT(ISBLANK(Inputs_A!D19)),"user (CPI energy override)",IF(ISBLANK(Inputs_A!C19),"oil bridge, Brent default","oil bridge, Brent user")) -> oil bridge, Brent default | S29: =IF(ISBLANK(Inputs_A!E19),"default: wage-linked","user") -> default: wage-linked | T29: =IF(ISBLANK(Inputs_A!F19),"default: AR(1)","user") -> default: AR(1) | U29: =IF(ISBLANK(Inputs_A!G19),"default: carried forward","user") -> default: carried forward | V29: =IF(ISBLANK(Inputs_A!H19),"default: trend held","user") -> default: trend held
... A41: 2029Q2 | B41: =IF(A41<=Settings!$B$7,"Forecast","Beyond horizon") -> Beyond horizon | C41: =IF(ISBLANK(Inputs_A!C31),C40,Inputs_A!C31) -> 78.233333 | D41: =400*LN(C41/C40) -> 0 | E41: =Aux_Models!$B$6+Aux_Models!$B$7*D41 -> 1.8686902 | F41: =IF(ISBLANK(Inputs_A!D31),E41,100*LN(1+Inputs_A!D31/100)) -> 1.8686902 | G41: =IF(ISBLANK(Inputs_A!E31),"wage-linked",100*LN(1+Inputs_A!E31/100)) -> wage-linked | H41: =IF(ISBLANK(Inputs_A!F31),Aux_Models!$B$8+Aux_Models!$B$9*H40,Inputs_A!F31) -> -0.089995179 | I41: =AVERAGE(H40:H41) -> -0.092817702 | J41: =IF(ISBLANK(Inputs_A!G31),J40,Inputs_A!G31) -> 1.6004715 | K41: =IF(ISBLANK(Inputs_A!H31),K33,100*LN(1+Inputs_A!H31/100)) -> 3.9909759 | L41: =AVERAGE(K34:K41) -> -0.099538212 | M41: =IF(ISBLANK(Inputs_A!I31),0,Inputs_A!I31) -> 0 | N41: =IF(ISBLANK(Inputs_A!J31),0,Inputs_A!J31) -> 0 | O41: =IF(ISBLANK(Inputs_A!K31),0,Inputs_A!K31) -> 0 | P41: =IF(ISBLANK(Inputs_A!L31),0,Inputs_A!L31) -> 0 | Q41: =IF(ISBLANK(Inputs_A!C31),"default: carried forward","user") -> default: carried forward | R41: =IF(NOT(ISBLANK(Inputs_A!D31)),"user (CPI energy override)",IF(ISBLANK(Inputs_A!C31),"oil bridge, Brent default","oil bridge, Brent user")) -> oil bridge, Brent default | S41: =IF(ISBLANK(Inputs_A!E31),"default: wage-linked","user") -> default: wage-linked | T41: =IF(ISBLANK(Inputs_A!F31),"default: AR(1)","user") -> default: AR(1) | U41: =IF(ISBLANK(Inputs_A!G31),"default: carried forward","user") -> default: carried forward | V41: =IF(ISBLANK(Inputs_A!H31),"default: trend held","user") -> default: trend held

Sheet Model_Inputs_B
A1: Model inputs actually used (Exercise B): transformed assumptions
A2: Light green = formulas. This is how the engine interprets Inputs_B (the engine recomputes the same transformations in Python; a test confirms they agree). Relative prices grpe = gE - gw and grpf = gF - gw need the simulated wage growth, so they are produced by the engine (see the engine's Model_Inputs_Engine sheet).
A6: Quarter | B6: Status | C6: Brent used | D6: Brent growth | E6: CPI energy growth from oil bridge | F6: CPI energy growth USED (model gE) | G6: CPI food growth USED (model gF) | H6: GSCPI used | I6: Shortage term (2-qtr mean) | J6: V/U used | K6: Productivity growth used | L6: Trend productivity magpty (8-qtr mean) | M6: Add-factor gw | N6: Add-factor gcpi | O6: Add-factor cf10 | P6: Add-factor cf1 | Q6: Brent: source | R6: CPI energy: source | S6: CPI food: source | T6: GSCPI: source | U6: V/U: source | V6: Productivity: source
C7: US$/bbl | D7: 400*dln | E7: 400*dln | F7: 400*dln | G7: 400*dln | H7: std devs | I7: std devs | J7: ratio | K7: 400*dln | L7: 400*dln | M7: pp | N7: pp | O7: pp | P7: pp
A8: 2021Q1 | B8: History | C8: =History!B16 -> 60.6 | F8: =History!N16 -> 44.055904 | G8: =History!O16 -> 1.2610235 | H8: =History!H16 -> 1.9166773 | I8: =History!T16 -> 1.3591037 | J8: =History!I16 -> 0.78176069 | K8: =History!R16 -> 2.8649674 | L8: =History!S16 -> 4.2386431
A9: 2021Q2 | B9: History | C9: =History!B17 -> 68.633333 | D9: =400*LN(C9/C8) -> 49.793373 | F9: =History!N17 -> 6.8841559 | G9: =History!O17 -> 6.3708245 | H9: =History!H17 -> 2.8931447 | I9: =History!T17 -> 2.404911 | J9: =History!I17 -> 1.0394455 | K9: =History!R17 -> 0.83221266 | L9: =History!S17 -> 4.0353301
A10: 2021Q3 | B10: History | C10: =History!B18 -> 73 | D10: =400*LN(C10/C9) -> 24.672446 | F10: =History!N18 -> 19.546804 | G10: =History!O18 -> 7.7065267 | H10: =History!H18 -> 3.248395 | I10: =History!T18 -> 3.0707698 | J10: =History!I18 -> 1.3282812 | K10: =History!R18 -> -2.4369499 | L10: =History!S18 -> 3.1715554
A11: 2021Q4 | B11: History | C11: =History!B19 -> 79.6 | D11: =400*LN(C11/C10) -> 34.621861 | F11: =History!N19 -> 35.247976 | G11: =History!O19 -> 9.0604705 | H11: =History!H19 -> 4.2794147 | I11: =History!T19 -> 3.7639048 | J11: =History!I19 -> 1.6638248 | K11: =History!R19 -> 2.2649099 | L11: =History!S19 -> 2.9891538
A12: 2022Q1 | B12: History | C12: =History!B20 -> 98.966667 | D12: =400*LN(C12/C11) -> 87.1076 | F12: =History!N20 -> 49.379776 | G12: =History!O20 -> 10.606802 | H12: =History!H20 -> 3.1419513 | I12: =History!T20 -> 3.710683 | J12: =History!I20 -> 1.8639949 | K12: =History!R20 -> -5.0579243 | L12: =History!S20 -> 2.5590281
A13: 2022Q2 | B13: History | C13: =History!B21 -> 112.76667 | D13: =400*LN(C13/C12) -> 52.215078 | F13: =History!N21 -> 34.565614 | G13: =History!O21 -> 12.377149 | H13: =History!H21 -> 2.935063 | I13: =History!T21 -> 3.0385072 | J13: =History!I21 -> 1.9320854 | K13: =History!R21 -> -2.9735579 | L13: =History!S21 -> -0.18801475
A14: 2022Q3 | B14: History | C14: =History!B22 -> 99.233333 | D14: =400*LN(C14/C13) -> -51.138723 | F14: =History!N22 -> -46.617389 | G14: =History!O22 -> 10.447792 | H14: =History!H22 -> 1.5306163 | I14: =History!T22 -> 2.2328397 | J14: =History!I22 -> 1.8631929 | K14: =History!R22 -> 0.23036525 | L14: =History!S22 -> -0.93613823
A15: 2022Q4 | B15: History | C15: =History!B23 -> 88.366667 | D15: =400*LN(C15/C14) -> -46.391662 | F15: =History!N23 -> -10.714022 | G15: =History!O23 -> 6.2305252 | H15: =History!H23 -> 1.3098957 | I15: =History!T23 -> 1.420256 | J15: =History!I23 -> 1.81216 | K15: =History!R23 -> 2.2745767 | L15: =History!S23 -> -0.25017501
A16: 2023Q1 | B16: History | C16: =History!B24 -> 81.433333 | D16: =400*LN(C16/C15) -> -32.684054 | F16: =History!N24 -> -4.8658536 | G16: =History!O24 -> 3.4350358 | H16: =History!H24 -> -0.15327933 | I16: =History!T24 -> 0.57830817 | J16: =History!I24 -> 1.693347 | K16: =History!R24 -> 0.91129859 | L16: =History!S24 -> -0.49438362
A17: 2023Q2 | B17: History | C17: =History!B25 -> 78.233333 | D17: =400*LN(C17/C16) -> -16.03555 | F17: =History!N25 -> -10.249406 | G17: =History!O25 -> 2.253478 | H17: =History!H25 -> -1.3193497 | I17: =History!T25 -> -0.7363145 | J17: =History!I25 -> 1.6004715 | K17: =History!R25 -> 3.9909759 | L17: =History!S25 -> -0.099538212
A18: 2023Q3 | B18: =IF(A18<=Settings!$B$7,"Forecast","Beyond horizon") -> Forecast | C18: =IF(ISBLANK(Inputs_B!C8),C17,Inputs_B!C8) -> 86.766667 | D18: =400*LN(C18/C17) -> 41.410684 | E18: =Aux_Models!$B$6+Aux_Models!$B$7*D18 -> 14.440649 | F18: =IF(ISBLANK(Inputs_B!D8),E18,100*LN(1+Inputs_B!D8/100)) -> 23.811299 | G18: =IF(ISBLANK(Inputs_B!E8),"wage-linked",100*LN(1+Inputs_B!E8/100)) -> 2.4912565 | H18: =IF(ISBLANK(Inputs_B!F8),Aux_Models!$B$8+Aux_Models!$B$9*H17,Inputs_B!F8) -> -0.86747033 | I18: =AVERAGE(H17:H18) -> -1.09341 | J18: =IF(ISBLANK(Inputs_B!G8),J17,Inputs_B!G8) -> 1.4708748 | K18: =IF(ISBLANK(Inputs_B!H8),K10,100*LN(1+Inputs_B!H8/100)) -> 4.9315938 | L18: =AVERAGE(K11:K18) -> 0.82152974 | M18: =IF(ISBLANK(Inputs_B!I8),0,Inputs_B!I8) -> 0 | N18: =IF(ISBLANK(Inputs_B!J8),0,Inputs_B!J8) -> 0 | O18: =IF(ISBLANK(Inputs_B!K8),0,Inputs_B!K8) -> 0 | P18: =IF(ISBLANK(Inputs_B!L8),0,Inputs_B!L8) -> 0 | Q18: =IF(ISBLANK(Inputs_B!C8),"default: carried forward","user") -> user | R18: =IF(NOT(ISBLANK(Inputs_B!D8)),"user (CPI energy override)",IF(ISBLANK(Inputs_B!C8),"oil bridge, Brent default","oil bridge, Brent user")) -> user (CPI energy override) | S18: =IF(ISBLANK(Inputs_B!E8),"default: wage-linked","user") -> user | T18: =IF(ISBLANK(Inputs_B!F8),"default: AR(1)","user") -> user | U18: =IF(ISBLANK(Inputs_B!G8),"default: carried forward","user") -> user | V18: =IF(ISBLANK(Inputs_B!H8),"default: trend held","user") -> user
A19: 2023Q4 | B19: =IF(A19<=Settings!$B$7,"Forecast","Beyond horizon") -> Forecast | C19: =IF(ISBLANK(Inputs_B!C9),C18,Inputs_B!C9) -> 84.066667 | D19: =400*LN(C19/C18) -> -12.644955 | E19: =Aux_Models!$B$6+Aux_Models!$B$7*D19 -> -1.9702191 | F19: =IF(ISBLANK(Inputs_B!D9),E19,100*LN(1+Inputs_B!D9/100)) -> -16.549678 | G19: =IF(ISBLANK(Inputs_B!E9),"wage-linked",100*LN(1+Inputs_B!E9/100)) -> 2.5260796 | H19: =IF(ISBLANK(Inputs_B!F9),Aux_Models!$B$8+Aux_Models!$B$9*H18,Inputs_B!F9) -> -0.099495667 | I19: =AVERAGE(H18:H19) -> -0.483483 | J19: =IF(ISBLANK(Inputs_B!G9),J18,Inputs_B!G9) -> 1.3514565 | K19: =IF(ISBLANK(Inputs_B!H9),K11,100*LN(1+Inputs_B!H9/100)) -> 3.8647303 | L19: =AVERAGE(K12:K19) -> 1.0215073 | M19: =IF(ISBLANK(Inputs_B!I9),0,Inputs_B!I9) -> 0 | N19: =IF(ISBLANK(Inputs_B!J9),0,Inputs_B!J9) -> 0 | O19: =IF(ISBLANK(Inputs_B!K9),0,Inputs_B!K9) -> 0 | P19: =IF(ISBLANK(Inputs_B!L9),0,Inputs_B!L9) -> 0 | Q19: =IF(ISBLANK(Inputs_B!C9),"default: carried forward","user") -> user | R19: =IF(NOT(ISBLANK(Inputs_B!D9)),"user (CPI energy override)",IF(ISBLANK(Inputs_B!C9),"oil bridge, Brent default","oil bridge, Brent user")) -> user (CPI energy override) | S19: =IF(ISBLANK(Inputs_B!E9),"default: wage-linked","user") -> user | T19: =IF(ISBLANK(Inputs_B!F9),"default: AR(1)","user") -> user | U19: =IF(ISBLANK(Inputs_B!G9),"default: carried forward","user") -> user | V19: =IF(ISBLANK(Inputs_B!H9),"default: trend held","user") -> user
A20: 2024Q1 | B20: =IF(A20<=Settings!$B$7,"Forecast","Beyond horizon") -> Forecast | C20: =IF(ISBLANK(Inputs_B!C10),C19,Inputs_B!C10) -> 83.133333 | D20: =400*LN(C20/C19) -> -4.4657561 | E20: =Aux_Models!$B$6+Aux_Models!$B$7*D20 -> 0.51292169 | F20: =IF(ISBLANK(Inputs_B!D10),E20,100*LN(1+Inputs_B!D10/100)) -> 11.134249 | G20: =IF(ISBLANK(Inputs_B!E10),"wage-linked",100*LN(1+Inputs_B!E10/100)) -> 1.6386249 | H20: =IF(ISBLANK(Inputs_B!F10),Aux_Models!$B$8+Aux_Models!$B$9*H19,Inputs_B!F10) -> -0.28298667 | I20: =AVERAGE(H19:H20) -> -0.19124117 | J20: =IF(ISBLANK(Inputs_B!G10),J19,Inputs_B!G10) -> 1.3045564 | K20: =IF(ISBLANK(Inputs_B!H10),K12,100*LN(1+Inputs_B!H10/100)) -> 0.23175379 | L20: =AVERAGE(K13:K20) -> 1.682717 | M20: =IF(ISBLANK(Inputs_B!I10),0,Inputs_B!I10) -> 0 | N20: =IF(ISBLANK(Inputs_B!J10),0,Inputs_B!J10) -> 0 | O20: =IF(ISBLANK(Inputs_B!K10),0,Inputs_B!K10) -> 0 | P20: =IF(ISBLANK(Inputs_B!L10),0,Inputs_B!L10) -> 0 | Q20: =IF(ISBLANK(Inputs_B!C10),"default: carried forward","user") -> user | R20: =IF(NOT(ISBLANK(Inputs_B!D10)),"user (CPI energy override)",IF(ISBLANK(Inputs_B!C10),"oil bridge, Brent default","oil bridge, Brent user")) -> user (CPI energy override) | S20: =IF(ISBLANK(Inputs_B!E10),"default: wage-linked","user") -> user | T20: =IF(ISBLANK(Inputs_B!F10),"default: AR(1)","user") -> user | U20: =IF(ISBLANK(Inputs_B!G10),"default: carried forward","user") -> user | V20: =IF(ISBLANK(Inputs_B!H10),"default: trend held","user") -> user
A21: 2024Q2 | B21: =IF(A21<=Settings!$B$7,"Forecast","Beyond horizon") -> Forecast | C21: =IF(ISBLANK(Inputs_B!C11),C20,Inputs_B!C11) -> 84.9 | D21: =400*LN(C21/C20) -> 8.4113395 | E21: =Aux_Models!$B$6+Aux_Models!$B$7*D21 -> 4.422307 | F21: =IF(ISBLANK(Inputs_B!D11),E21,100*LN(1+Inputs_B!D11/100)) -> -14.681738 | G21: =IF(ISBLANK(Inputs_B!E11),"wage-linked",100*LN(1+Inputs_B!E11/100)) -> 2.2221806 | H21: =IF(ISBLANK(Inputs_B!F11),Aux_Models!$B$8+Aux_Models!$B$9*H20,Inputs_B!F11) -> -0.61931533 | I21: =AVERAGE(H20:H21) -> -0.451151 | J21: =IF(ISBLANK(Inputs_B!G11),J20,Inputs_B!G11) -> 1.136691 | K21: =IF(ISBLANK(Inputs_B!H11),K13,100*LN(1+Inputs_B!H11/100)) -> 3.644696 | L21: =AVERAGE(K14:K21) -> 2.5099988 | M21: =IF(ISBLANK(Inputs_B!I11),0,Inputs_B!I11) -> 0 | N21: =IF(ISBLANK(Inputs_B!J11),0,Inputs_B!J11) -> 0 | O21: =IF(ISBLANK(Inputs_B!K11),0,Inputs_B!K11) -> 0 | P21: =IF(ISBLANK(Inputs_B!L11),0,Inputs_B!L11) -> 0 | Q21: =IF(ISBLANK(Inputs_B!C11),"default: carried forward","user") -> user | R21: =IF(NOT(ISBLANK(Inputs_B!D11)),"user (CPI energy override)",IF(ISBLANK(Inputs_B!C11),"oil bridge, Brent default","oil bridge, Brent user")) -> user (CPI energy override) | S21: =IF(ISBLANK(Inputs_B!E11),"default: wage-linked","user") -> user | T21: =IF(ISBLANK(Inputs_B!F11),"default: AR(1)","user") -> user | U21: =IF(ISBLANK(Inputs_B!G11),"default: carried forward","user") -> user | V21: =IF(ISBLANK(Inputs_B!H11),"default: trend held","user") -> user
A22: 2024Q3 | B22: =IF(A22<=Settings!$B$7,"Forecast","Beyond horizon") -> Forecast | C22: =IF(ISBLANK(Inputs_B!C12),C21,Inputs_B!C12) -> 80.166667 | D22: =400*LN(C22/C21) -> -22.946517 | E22: =Aux_Models!$B$6+Aux_Models!$B$7*D22 -> -5.0976925 | F22: =IF(ISBLANK(Inputs_B!D12),E22,100*LN(1+Inputs_B!D12/100)) -> -8.1358245 | G22: =IF(ISBLANK(Inputs_B!E12),"wage-linked",100*LN(1+Inputs_B!E12/100)) -> 2.6043672 | H22: =IF(ISBLANK(Inputs_B!F12),Aux_Models!$B$8+Aux_Models!$B$9*H21,Inputs_B!F12) -> 0.096915333 | I22: =AVERAGE(H21:H22) -> -0.2612 | J22: =IF(ISBLANK(Inputs_B!G12),J21,Inputs_B!G12) -> 1.0418372 | K22: =IF(ISBLANK(Inputs_B!H12),K14,100*LN(1+Inputs_B!H12/100)) -> 3.6186807 | L22: =AVERAGE(K15:K22) -> 2.9335382 | M22: =IF(ISBLANK(Inputs_B!I12),0,Inputs_B!I12) -> 0 | N22: =IF(ISBLANK(Inputs_B!J12),0,Inputs_B!J12) -> 0 | O22: =IF(ISBLANK(Inputs_B!K12),0,Inputs_B!K12) -> 0 | P22: =IF(ISBLANK(Inputs_B!L12),0,Inputs_B!L12) -> 0 | Q22: =IF(ISBLANK(Inputs_B!C12),"default: carried forward","user") -> user | R22: =IF(NOT(ISBLANK(Inputs_B!D12)),"user (CPI energy override)",IF(ISBLANK(Inputs_B!C12),"oil bridge, Brent default","oil bridge, Brent user")) -> user (CPI energy override) | S22: =IF(ISBLANK(Inputs_B!E12),"default: wage-linked","user") -> user | T22: =IF(ISBLANK(Inputs_B!F12),"default: AR(1)","user") -> user | U22: =IF(ISBLANK(Inputs_B!G12),"default: carried forward","user") -> user | V22: =IF(ISBLANK(Inputs_B!H12),"default: trend held","user") -> user
A23: 2024Q4 | B23: =IF(A23<=Settings!$B$7,"Forecast","Beyond horizon") -> Forecast | C23: =IF(ISBLANK(Inputs_B!C13),C22,Inputs_B!C13) -> 74.633333 | D23: =400*LN(C23/C22) -> -28.608226 | E23: =Aux_Models!$B$6+Aux_Models!$B$7*D23 -> -6.8165431 | F23: =IF(ISBLANK(Inputs_B!D13),E23,100*LN(1+Inputs_B!D13/100)) -> 10.350435 | G23: =IF(ISBLANK(Inputs_B!E13),"wage-linked",100*LN(1+Inputs_B!E13/100)) -> 3.2554137 | H23: =IF(ISBLANK(Inputs_B!F13),Aux_Models!$B$8+Aux_Models!$B$9*H22,Inputs_B!F13) -> -0.36296467 | I23: =AVERAGE(H22:H23) -> -0.13302467 | J23: =IF(ISBLANK(Inputs_B!G13),J22,Inputs_B!G13) -> 1.0610687 | K23: =IF(ISBLANK(Inputs_B!H13),K15,100*LN(1+Inputs_B!H13/100)) -> 1.4108755 | L23: =AVERAGE(K16:K23) -> 2.8255756 | M23: =IF(ISBLANK(Inputs_B!I13),0,Inputs_B!I13) -> 0 | N23: =IF(ISBLANK(Inputs_B!J13),0,Inputs_B!J13) -> 0 | O23: =IF(ISBLANK(Inputs_B!K13),0,Inputs_B!K13) -> 0 | P23: =IF(ISBLANK(Inputs_B!L13),0,Inputs_B!L13) -> 0 | Q23: =IF(ISBLANK(Inputs_B!C13),"default: carried forward","user") -> user | R23: =IF(NOT(ISBLANK(Inputs_B!D13)),"user (CPI energy override)",IF(ISBLANK(Inputs_B!C13),"oil bridge, Brent default","oil bridge, Brent user")) -> user (CPI energy override) | S23: =IF(ISBLANK(Inputs_B!E13),"default: wage-linked","user") -> user | T23: =IF(ISBLANK(Inputs_B!F13),"default: AR(1)","user") -> user | U23: =IF(ISBLANK(Inputs_B!G13),"default: carried forward","user") -> user | V23: =IF(ISBLANK(Inputs_B!H13),"default: trend held","user") -> user
A24: 2025Q1 | B24: =IF(A24<=Settings!$B$7,"Forecast","Beyond horizon") -> Forecast | C24: =IF(ISBLANK(Inputs_B!C14),C23,Inputs_B!C14) -> 75.666667 | D24: =400*LN(C24/C23) -> 5.5001976 | E24: =Aux_Models!$B$6+Aux_Models!$B$7*D24 -> 3.5385071 | F24: =IF(ISBLANK(Inputs_B!D14),E24,100*LN(1+Inputs_B!D14/100)) -> -1.3215579 | G24: =IF(ISBLANK(Inputs_B!E14),"wage-linked",100*LN(1+Inputs_B!E14/100)) -> 3.4141575 | H24: =IF(ISBLANK(Inputs_B!F14),Aux_Models!$B$8+Aux_Models!$B$9*H23,Inputs_B!F14) -> -0.208122 | I24: =AVERAGE(H23:H24) -> -0.28554333 | J24: =IF(ISBLANK(Inputs_B!G14),J23,Inputs_B!G14) -> 1.0248329 | K24: =IF(ISBLANK(Inputs_B!H14),K16,100*LN(1+Inputs_B!H14/100)) -> -0.88723858 | L24: =AVERAGE(K17:K24) -> 2.6007584 | M24: =IF(ISBLANK(Inputs_B!I14),0,Inputs_B!I14) -> 0 | N24: =IF(ISBLANK(Inputs_B!J14),0,Inputs_B!J14) -> 0 | O24: =IF(ISBLANK(Inputs_B!K14),0,Inputs_B!K14) -> 0 | P24: =IF(ISBLANK(Inputs_B!L14),0,Inputs_B!L14) -> 0 | Q24: =IF(ISBLANK(Inputs_B!C14),"default: carried forward","user") -> user | R24: =IF(NOT(ISBLANK(Inputs_B!D14)),"user (CPI energy override)",IF(ISBLANK(Inputs_B!C14),"oil bridge, Brent default","oil bridge, Brent user")) -> user (CPI energy override) | S24: =IF(ISBLANK(Inputs_B!E14),"default: wage-linked","user") -> user | T24: =IF(ISBLANK(Inputs_B!F14),"default: AR(1)","user") -> user | U24: =IF(ISBLANK(Inputs_B!G14),"default: carried forward","user") -> user | V24: =IF(ISBLANK(Inputs_B!H14),"default: trend held","user") -> user
A25: 2025Q2 | B25: =IF(A25<=Settings!$B$7,"Forecast","Beyond horizon") -> Forecast | C25: =IF(ISBLANK(Inputs_B!C15),C24,Inputs_B!C15) -> 67.8 | D25: =400*LN(C25/C24) -> -43.910214 | E25: =Aux_Models!$B$6+Aux_Models!$B$7*D25 -> -11.462106 | F25: =IF(ISBLANK(Inputs_B!D15),E25,100*LN(1+Inputs_B!D15/100)) -> -3.3816974 | G25: =IF(ISBLANK(Inputs_B!E15),"wage-linked",100*LN(1+Inputs_B!E15/100)) -> 2.5260169 | H25: =IF(ISBLANK(Inputs_B!F15),Aux_Models!$B$8+Aux_Models!$B$9*H24,Inputs_B!F15) -> -0.053499 | I25: =AVERAGE(H24:H25) -> -0.1308105 | J25: =IF(ISBLANK(Inputs_B!G15),J24,Inputs_B!G15) -> 1.0072237 | K25: =IF(ISBLANK(Inputs_B!H15),K17,100*LN(1+Inputs_B!H15/100)) -> 4.1032675 | L25: =AVERAGE(K18:K25) -> 2.6147949 | M25: =IF(ISBLANK(Inputs_B!I15),0,Inputs_B!I15) -> 0 | N25: =IF(ISBLANK(Inputs_B!J15),0,Inputs_B!J15) -> 0 | O25: =IF(ISBLANK(Inputs_B!K15),0,Inputs_B!K15) -> 0 | P25: =IF(ISBLANK(Inputs_B!L15),0,Inputs_B!L15) -> 0 | Q25: =IF(ISBLANK(Inputs_B!C15),"default: carried forward","user") -> user | R25: =IF(NOT(ISBLANK(Inputs_B!D15)),"user (CPI energy override)",IF(ISBLANK(Inputs_B!C15),"oil bridge, Brent default","oil bridge, Brent user")) -> user (CPI energy override) | S25: =IF(ISBLANK(Inputs_B!E15),"default: wage-linked","user") -> user | T25: =IF(ISBLANK(Inputs_B!F15),"default: AR(1)","user") -> user | U25: =IF(ISBLANK(Inputs_B!G15),"default: carried forward","user") -> user | V25: =IF(ISBLANK(Inputs_B!H15),"default: trend held","user") -> user
A26: 2025Q3 | B26: =IF(A26<=Settings!$B$7,"Forecast","Beyond horizon") -> Forecast | C26: =IF(ISBLANK(Inputs_B!C16),C25,Inputs_B!C16) -> 69.066667 | D26: =400*LN(C26/C25) -> 7.4040107 | E26: =Aux_Models!$B$6+Aux_Models!$B$7*D26 -> 4.1164899 | F26: =IF(ISBLANK(Inputs_B!D16),E26,100*LN(1+Inputs_B!D16/100)) -> 5.9463678 | G26: =IF(ISBLANK(Inputs_B!E16),"wage-linked",100*LN(1+Inputs_B!E16/100)) -> 3.0729925 | H26: =IF(ISBLANK(Inputs_B!F16),Aux_Models!$B$8+Aux_Models!$B$9*H25,Inputs_B!F16) -> -0.029837667 | I26: =AVERAGE(H25:H26) -> -0.041668333 | J26: =IF(ISBLANK(Inputs_B!G16),J25,Inputs_B!G16) -> 0.95147594 | K26: =IF(ISBLANK(Inputs_B!H16),K18,100*LN(1+Inputs_B!H16/100)) -> 5.0756387 | L26: =AVERAGE(K19:K26) -> 2.6328005 | M26: =IF(ISBLANK(Inputs_B!I16),0,Inputs_B!I16) -> 0 | N26: =IF(ISBLANK(Inputs_B!J16),0,Inputs_B!J16) -> 0 | O26: =IF(ISBLANK(Inputs_B!K16),0,Inputs_B!K16) -> 0 | P26: =IF(ISBLANK(Inputs_B!L16),0,Inputs_B!L16) -> 0 | Q26: =IF(ISBLANK(Inputs_B!C16),"default: carried forward","user") -> user | R26: =IF(NOT(ISBLANK(Inputs_B!D16)),"user (CPI energy override)",IF(ISBLANK(Inputs_B!C16),"oil bridge, Brent default","oil bridge, Brent user")) -> user (CPI energy override) | S26: =IF(ISBLANK(Inputs_B!E16),"default: wage-linked","user") -> user | T26: =IF(ISBLANK(Inputs_B!F16),"default: AR(1)","user") -> user | U26: =IF(ISBLANK(Inputs_B!G16),"default: carried forward","user") -> user | V26: =IF(ISBLANK(Inputs_B!H16),"default: trend held","user") -> user
A27: 2025Q4 | B27: =IF(A27<=Settings!$B$7,"Forecast","Beyond horizon") -> Forecast | C27: =IF(ISBLANK(Inputs_B!C17),C26,Inputs_B!C17) -> 63.666667 | D27: =400*LN(C27/C26) -> -32.564433 | E27: =Aux_Models!$B$6+Aux_Models!$B$7*D27 -> -8.0176164 | F27: =IF(ISBLANK(Inputs_B!D17),E27,100*LN(1+Inputs_B!D17/100)) -> 6.9559109 | G27: =IF(ISBLANK(Inputs_B!E17),"wage-linked",100*LN(1+Inputs_B!E17/100)) -> 2.9660055 | H27: =IF(ISBLANK(Inputs_B!F17),Aux_Models!$B$8+Aux_Models!$B$9*H26,Inputs_B!F17) -> 0.033617 | I27: =AVERAGE(H26:H27) -> 0.0018896667 | J27: =IF(ISBLANK(Inputs_B!G17),J26,Inputs_B!G17) -> 0.89506898 | K27: =IF(ISBLANK(Inputs_B!H17),K19,100*LN(1+Inputs_B!H17/100)) -> 1.56485 | L27: =AVERAGE(K20:K27) -> 2.3453155 | M27: =IF(ISBLANK(Inputs_B!I17),0,Inputs_B!I17) -> 0 | N27: =IF(ISBLANK(Inputs_B!J17),0,Inputs_B!J17) -> 0 | O27: =IF(ISBLANK(Inputs_B!K17),0,Inputs_B!K17) -> 0 | P27: =IF(ISBLANK(Inputs_B!L17),0,Inputs_B!L17) -> 0 | Q27: =IF(ISBLANK(Inputs_B!C17),"default: carried forward","user") -> user | R27: =IF(NOT(ISBLANK(Inputs_B!D17)),"user (CPI energy override)",IF(ISBLANK(Inputs_B!C17),"oil bridge, Brent default","oil bridge, Brent user")) -> user (CPI energy override) | S27: =IF(ISBLANK(Inputs_B!E17),"default: wage-linked","user") -> user | T27: =IF(ISBLANK(Inputs_B!F17),"default: AR(1)","user") -> user | U27: =IF(ISBLANK(Inputs_B!G17),"default: carried forward","user") -> user | V27: =IF(ISBLANK(Inputs_B!H17),"default: trend held","user") -> user
A28: 2026Q1 | B28: =IF(A28<=Settings!$B$7,"Forecast","Beyond horizon") -> Forecast | C28: =IF(ISBLANK(Inputs_B!C18),C27,Inputs_B!C18) -> 80.533333 | D28: =400*LN(C28/C27) -> 94.004015 | E28: =Aux_Models!$B$6+Aux_Models!$B$7*D28 -> 30.407572 | F28: =IF(ISBLANK(Inputs_B!D18),E28,100*LN(1+Inputs_B!D18/100)) -> 37.910893 | G28: =IF(ISBLANK(Inputs_B!E18),"wage-linked",100*LN(1+Inputs_B!E18/100)) -> 2.2811407 | H28: =IF(ISBLANK(Inputs_B!F18),Aux_Models!$B$8+Aux_Models!$B$9*H27,Inputs_B!F18) -> 0.49244233 | I28: =AVERAGE(H27:H28) -> 0.26302967 | J28: =IF(ISBLANK(Inputs_B!G18),J27,Inputs_B!G18) -> 0.9490937 | K28: =IF(ISBLANK(Inputs_B!H18),K20,100*LN(1+Inputs_B!H18/100)) -> 0.8169281 | L28: =AVERAGE(K21:K28) -> 2.4184623 | M28: =IF(ISBLANK(Inputs_B!I18),0,Inputs_B!I18) -> 0 | N28: =IF(ISBLANK(Inputs_B!J18),0,Inputs_B!J18) -> 0 | O28: =IF(ISBLANK(Inputs_B!K18),0,Inputs_B!K18) -> 0 | P28: =IF(ISBLANK(Inputs_B!L18),0,Inputs_B!L18) -> 0 | Q28: =IF(ISBLANK(Inputs_B!C18),"default: carried forward","user") -> user | R28: =IF(NOT(ISBLANK(Inputs_B!D18)),"user (CPI energy override)",IF(ISBLANK(Inputs_B!C18),"oil bridge, Brent default","oil bridge, Brent user")) -> user (CPI energy override) | S28: =IF(ISBLANK(Inputs_B!E18),"default: wage-linked","user") -> user | T28: =IF(ISBLANK(Inputs_B!F18),"default: AR(1)","user") -> user | U28: =IF(ISBLANK(Inputs_B!G18),"default: carried forward","user") -> user | V28: =IF(ISBLANK(Inputs_B!H18),"default: trend held","user") -> user
